Workbook

Sheet Cover
C11: NIKE, Inc. (NYSE: NKE) | N11: Prepared by Chetan Puvvadi
C12: 3-Statement Model, DCF Valuation & Comparable Company Analysis | N12: Portfolio Project -- Built Using CFI FMVA Formatting Conventions
C14: Table of Contents | K14: Model Checks
C16: Outputs | K16: Balance Sheet Unbalanced? | N16: =IF(SUM(Model!D78:K78)=0,"No","Yes") -> No
C17: Valuation summary dashboard: implied share price by method, key metrics, WACC assumptions. | K17: WACC Below Terminal Growth Rate? | N17: =IF(Inputs!F116>Inputs!F117,"No","Yes") -> No
C18: Inputs | K18: Diluted EPS Negative in Any Forecast Year? | N18: =IF(COUNTIF(Model!G37:K37,"<0")=0,"No","Yes") -> No
C19: All model assumptions and drivers -- revenue growth, margins, working capital, capex, capital structure, WACC.
C20: Model
C21: 3-statement model (Income Statement, Balance Sheet, Cash Flow) plus Working Capital/PP&E and Capital Structure schedules.
C22: DCF
C23: Discounted cash flow valuation -- unlevered FCF, terminal value, enterprise/equity value, sensitivity.
C24: Comps
C25: Comparable company (trading comps) analysis and NIKE implied valuation.
C31: NIKE, Inc. Financial Model -- Portfolio Project
C32: Independent work product built by Chetan Puvvadi to learn and demonstrate 3-statement modeling, DCF
C33: valuation, and comparable company analysis technique and formatting conventions in the style taught by the
C34: Corporate Finance Institute (CFI) FMVA program. This model is not affiliated with, endorsed by, or reviewed
C35: by CFI, NIKE, Inc., or any of the peer companies referenced in the Comparable Company Analysis.
... C38: not investment advice and should not be relied upon for any investment decision.

Sheet Outputs
B3: Valuation Summary Dashboard
B5: Current Share Price | D5: =Inputs!F119 -> 39.6
B7: Valuation Method | D7: Implied Share Price | E7: Upside / (Downside)
B8: DCF -- Perpetuity Growth Method | D8: =DCF!F35 -> 45.29919 | E8: =DCF!F37 -> 0.14391894
B9: DCF -- Exit Multiple Method | D9: =DCF!F36 -> 49.099603 | E9: =DCF!F38 -> 0.23988896
B10: Comps -- EV/Revenue Method | D10: =Comps!F30 -> 37.71379 | E10: =D10/D5-1 -> -0.047631577
B11: Comps -- EV/EBITDA Method | D11: =Comps!F31 -> 32.966099 | E11: =D11/D5-1 -> -0.16752274
B12: Comps -- P/E Method | D12: =Comps!F32 -> 32.489502 | E12: =D12/D5-1 -> -0.17955803
B14: KEY METRICS -- FY2026A ACTUAL vs. FY2031E FORECAST
D16: FY2026A | E16: FY2031E
B17: Total Revenue ($mm) | D17: =Model!F18 -> 46398 | E17: =Model!K18 -> 52420.806
B18: Revenue CAGR, FY26A-FY31E | E18: =(E17/D17)^(1/5)-1 -> 0.024709791
B19: Gross Margin, % | D19: =Model!F21/Model!F18 -> 0.42913488 | E19: =Model!K21/Model!K18 -> 0.447
B20: Operating Margin (EBIT), % | D20: =Model!F27/Model!F18 -> 0.081835424 | E20: =Model!K27/Model!K18 -> 0.128
B21: Net Income ($mm) | D21: =Model!F34 -> 3108 | E21: =Model!K34 -> 5069.1116
B22: Diluted EPS ($) | D22: =Model!F37 -> 2.098582 | E22: =Model!K37 -> 3.6914385
B23: Diluted Shares Outstanding (mm) | D23: =Model!F36 -> 1481 | E23: =Model!K36 -> 1373.2076
B24: Unlevered Free Cash Flow ($mm) | E24: =DCF!K13 -> 4787.9488
B26: WACC & VALUATION ASSUMPTIONS
B28: WACC | D28: =Inputs!F116 -> 0.088188305
B29: Terminal Growth Rate | D29: =Inputs!F117 -> 0.02
B30: Exit EV/EBITDA Multiple | D30: =Inputs!F118 -> 10.505676
B53: All figures in USD unless stated. See DCF and Comps sheets for full build.

Sheet Inputs
B3: Assumptions & Drivers
B5: All figures in USD millions unless stated | D5: FY2024A | E5: FY2025A | F5: FY2026A | G5: FY2027E | H5: FY2028E | I5: FY2029E | J5: FY2030E | K5: FY2031E
B7: Days in Period | D7: 365 | E7: 365 | F7: 365 | G7: 365 | H7: 365 | I7: 365 | J7: 365 | K7: 365
B10: Driver Switch | C10: 2
B12: REVENUE GROWTH
B14: North America Revenue Growth, % | E14: =Model!E9/Model!D9-1 -> -0.085249579 | F14: =Model!F9/Model!E9-1 -> 0.047976701 | G14: {=INDEX(G16:G18,$C$10)} -> 0.048 | H14: {=INDEX(H16:H18,$C$10)} -> 0.04 | I14: {=INDEX(I16:I18,$C$10)} -> 0.04 | J14: {=INDEX(J16:J18,$C$10)} -> 0.038 | K14: {=INDEX(K16:K18,$C$10)} -> 0.04
B16: Best Case | G16: 0.068 | H16: 0.06 | I16: 0.06 | J16: 0.058 | K16: 0.06
B17: Base Case | G17: 0.048 | H17: 0.04 | I17: 0.04 | J17: 0.038 | K17: 0.04
B18: Worst Case | G18: 0.028 | H18: 0.02 | I18: 0.02 | J18: 0.018 | K18: 0.02
B21: EMEA Revenue Growth, % | E21: =Model!E10/Model!D10-1 -> -0.09921364 | F21: =Model!F10/Model!E10-1 -> 0.0256996 | G21: {=INDEX(G23:G25,$C$10)} -> 0.014 | H21: {=INDEX(H23:H25,$C$10)} -> 0.025 | I21: {=INDEX(I23:I25,$C$10)} -> 0.025 | J21: {=INDEX(J23:J25,$C$10)} -> 0.025 | K21: {=INDEX(K23:K25,$C$10)} -> 0.025
B23: =B16 -> Best Case | G23: 0.034 | H23: 0.045 | I23: 0.045 | J23: 0.045 | K23: 0.045
B24: =B17 -> Base Case | G24: 0.014 | H24: 0.025 | I24: 0.025 | J24: 0.025 | K24: 0.025
B25: =B18 -> Worst Case | G25: -0.006 | H25: 0.005 | I25: 0.005 | J25: 0.005 | K25: 0.005
B28: Greater China Revenue Growth, % | E28: =Model!E11/Model!D11-1 -> -0.12710404 | F28: =Model!F11/Model!E11-1 -> -0.11220771 | G28: {=INDEX(G30:G32,$C$10)} -> -0.128 | H28: {=INDEX(H30:H32,$C$10)} -> 0.01 | I28: {=INDEX(I30:I32,$C$10)} -> 0.01 | J28: {=INDEX(J30:J32,$C$10)} -> 0.01 | K28: {=INDEX(K30:K32,$C$10)} -> 0.02
B30: =B16 -> Best Case | G30: -0.108 | H30: 0.03 | I30: 0.03 | J30: 0.03 | K30: 0.04
B31: =B17 -> Base Case | G31: -0.128 | H31: 0.01 | I31: 0.01 | J31: 0.01 | K31: 0.02
B32: =B18 -> Worst Case | G32: -0.148 | H32: -0.01 | I32: -0.01 | J32: -0.01 | K32: 0
B35: APLA Revenue Growth, % | E35: =Model!E12/Model!D12-1 -> -0.071035815 | F35: =Model!F12/Model!E12-1 -> -0.0012797952 | G35: {=INDEX(G37:G39,$C$10)} -> -0.001 | H35: {=INDEX(H37:H39,$C$10)} -> 0.03 | I35: {=INDEX(I37:I39,$C$10)} -> 0.03 | J35: {=INDEX(J37:J39,$C$10)} -> 0.035 | K35: {=INDEX(K37:K39,$C$10)} -> 0.035
B37: =B16 -> Best Case | G37: 0.019 | H37: 0.05 | I37: 0.05 | J37: 0.055 | K37: 0.055
B38: =B17 -> Base Case | G38: -0.001 | H38: 0.03 | I38: 0.03 | J38: 0.035 | K38: 0.035
B39: =B18 -> Worst Case | G39: -0.021 | H39: 0.01 | I39: 0.01 | J39: 0.015 | K39: 0.015
B42: Global Brand Divisions Revenue Growth, % | E42: =Model!E13/Model!D13-1 -> 0.066666667 | F42: =Model!F13/Model!E13-1 -> 0.020833333 | G42: {=INDEX(G44:G46,$C$10)} -> 0.02 | H42: {=INDEX(H44:H46,$C$10)} -> 0.02 | I42: {=INDEX(I44:I46,$C$10)} -> 0.02 | J42: {=INDEX(J44:J46,$C$10)} -> 0.02 | K42: {=INDEX(K44:K46,$C$10)} -> 0.02
B44: =B16 -> Best Case | G44: 0.04 | H44: 0.04 | I44: 0.04 | J44: 0.04 | K44: 0.04
B45: =B17 -> Base Case | G45: 0.02 | H45: 0.02 | I45: 0.02 | J45: 0.02 | K45: 0.02
B46: =B18 -> Worst Case | G46: 0 | H46: 0 | I46: 0 | J46: 0 | K46: 0
B49: Converse Revenue Growth, % | E49: =Model!E16/Model!D16-1 -> -0.18731988 | F49: =Model!F16/Model!E16-1 -> -0.30614657 | G49: {=INDEX(G51:G53,$C$10)} -> -0.307 | H49: {=INDEX(H51:H53,$C$10)} -> -0.05 | I49: {=INDEX(I51:I53,$C$10)} -> -0.05 | J49: {=INDEX(J51:J53,$C$10)} -> 0 | K49: {=INDEX(K51:K53,$C$10)} -> 0.02
B51: =B16 -> Best Case | G51: -0.287 | H51: -0.03 | I51: -0.03 | J51: 0.02 | K51: 0.04
B52: =B17 -> Base Case | G52: -0.307 | H52: -0.05 | I52: -0.05 | J52: 0 | K52: 0.02
B53: =B18 -> Worst Case | G53: -0.327 | H53: -0.07 | I53: -0.07 | J53: -0.02 | K53: 0
N54: Alternative: Top-Down / Bottom-Up / Regression
B56: MARGIN & OPERATING EXPENSE DRIVERS
B58: Gross Margin, % (Scenario-Driven via Driver Switch) | D58: =Model!D21/Model!D18 -> 0.44560181 | E58: =Model!E21/Model!E18 -> 0.42734674 | F58: =Model!F21/Model!F18 -> 0.42913488 | G58: {=INDEX(G60:G62,$C$10)} -> 0.435 | H58: {=INDEX(H60:H62,$C$10)} -> 0.44 | I58: {=INDEX(I60:I62,$C$10)} -> 0.443 | J58: {=INDEX(J60:J62,$C$10)} -> 0.445 | K58: {=INDEX(K60:K62,$C$10)} -> 0.447
B60: =B16 -> Best Case | G60: 0.445 | H60: 0.45 | I60: 0.453 | J60: 0.455 | K60: 0.457
B61: =B17 -> Base Case | G61: 0.435 | H61: 0.44 | I61: 0.443 | J61: 0.445 | K61: 0.447
B62: =B18 -> Worst Case | G62: 0.425 | H62: 0.43 | I62: 0.433 | J62: 0.435 | K62: 0.437
B65: Demand Creation Expense (% of Revenue) | D65: =-Model!D23/Model!D18 -> 0.083427437 | E65: =-Model!E23/Model!E18 -> 0.10125462 | F65: =-Model!F23/Model!F18 -> 0.10246131 | G65: 0.101 | H65: 0.101 | I65: 0.101 | J65: 0.101 | K65: 0.101
B66: Operating Overhead Expense (% of Revenue) | D66: =-Model!D24/Model!D18 -> 0.23930143 | E66: =-Model!E24/Model!E18 -> 0.24615086 | F66: =-Model!F24/Model!F18 -> 0.24483814 | G66: 0.238 | H66: 0.233 | I66: 0.228 | J66: 0.223 | K66: 0.218
B67: Other Income (Expense) (% of Revenue) | G67: 0 | H67: 0 | I67: 0 | J67: 0 | K67: 0
N68: Alternative: COGS Margin, Cost per Unit
B70: WORKING CAPITAL DRIVERS
...

Sheet Model
B3: Income Statement
B5: All figures in USD millions unless stated | D5: FY2024A | E5: FY2025A | F5: FY2026A | G5: FY2027E | H5: FY2028E | I5: FY2029E | J5: FY2030E | K5: FY2031E
B7: NIKE BRAND REVENUE BY GEOGRAPHY
B9: North America | D9: 21396 | E9: 19572 | F9: 20511 | G9: =F9*(1+Inputs!G14) -> 21495.528 | H9: =G9*(1+Inputs!H14) -> 22355.349 | I9: =H9*(1+Inputs!I14) -> 23249.563 | J9: =I9*(1+Inputs!J14) -> 24133.046 | K9: =J9*(1+Inputs!K14) -> 25098.368
B10: EMEA | D10: 13607 | E10: 12257 | F10: 12572 | G10: =F10*(1+Inputs!G21) -> 12748.008 | H10: =G10*(1+Inputs!H21) -> 13066.708 | I10: =H10*(1+Inputs!I21) -> 13393.376 | J10: =I10*(1+Inputs!J21) -> 13728.21 | K10: =J10*(1+Inputs!K21) -> 14071.416
B11: Greater China | D11: 7545 | E11: 6586 | F11: 5847 | G11: =F11*(1+Inputs!G28) -> 5098.584 | H11: =G11*(1+Inputs!H28) -> 5149.5698 | I11: =H11*(1+Inputs!I28) -> 5201.0655 | J11: =I11*(1+Inputs!J28) -> 5253.0762 | K11: =J11*(1+Inputs!K28) -> 5358.1377
B12: APLA | D12: 6729 | E12: 6251 | F12: 6243 | G12: =F12*(1+Inputs!G35) -> 6236.757 | H12: =G12*(1+Inputs!H35) -> 6423.8597 | I12: =H12*(1+Inputs!I35) -> 6616.5755 | J12: =I12*(1+Inputs!J35) -> 6848.1556 | K12: =J12*(1+Inputs!K35) -> 7087.8411
B13: Global Brand Divisions | D13: 45 | E13: 48 | F13: 49 | G13: =F13*(1+Inputs!G42) -> 49.98 | H13: =G13*(1+Inputs!H42) -> 50.9796 | I13: =H13*(1+Inputs!I42) -> 51.999192 | J13: =I13*(1+Inputs!J42) -> 53.039176 | K13: =J13*(1+Inputs!K42) -> 54.099959
B14: NIKE Brand Revenue, Total | D14: =SUM(D9:D13) -> 49322 | E14: =SUM(E9:E13) -> 44714 | F14: =SUM(F9:F13) -> 45222 | G14: =SUM(G9:G13) -> 45628.857 | H14: =SUM(H9:H13) -> 47046.466 | I14: =SUM(I9:I13) -> 48512.579 | J14: =SUM(J9:J13) -> 50015.528 | K14: =SUM(K9:K13) -> 51669.863
B16: Converse | D16: 2082 | E16: 1692 | F16: 1174 | G16: =F16*(1+Inputs!G49) -> 813.582 | H16: =G16*(1+Inputs!H49) -> 772.9029 | I16: =H16*(1+Inputs!I49) -> 734.25775 | J16: =I16*(1+Inputs!J49) -> 734.25775 | K16: =J16*(1+Inputs!K49) -> 748.94291
B17: Corporate & Eliminations | D17: -42 | E17: -97 | F17: 2 | G17: =F17 -> 2 | H17: =G17 -> 2 | I17: =H17 -> 2 | J17: =I17 -> 2 | K17: =J17 -> 2
B18: Total Revenue | D18: =D14+D16+D17 -> 51362 | E18: =E14+E16+E17 -> 46309 | F18: =F14+F16+F17 -> 46398 | G18: =G14+G16+G17 -> 46444.439 | H18: =H14+H16+H17 -> 47821.369 | I18: =I14+I16+I17 -> 49248.837 | J18: =J14+J16+J17 -> 50751.786 | K18: =K14+K16+K17 -> 52420.806
B20: Cost of Sales | D20: -28475 | E20: -26519 | F20: -26487 | G20: =-G18*(1-Inputs!G58) -> -26241.108 | H20: =-H18*(1-Inputs!H58) -> -26779.967 | I20: =-I18*(1-Inputs!I58) -> -27431.602 | J20: =-J18*(1-Inputs!J58) -> -28167.241 | K20: =-K18*(1-Inputs!K58) -> -28988.705
B21: Gross Profit | D21: =D18+D20 -> 22887 | E21: =E18+E20 -> 19790 | F21: =F18+F20 -> 19911 | G21: =G18+G20 -> 20203.331 | H21: =H18+H20 -> 21041.403 | I21: =I18+I20 -> 21817.235 | J21: =J18+J20 -> 22584.545 | K21: =K18+K20 -> 23432.1
B23: Demand Creation Expense | D23: -4285 | E23: -4689 | F23: -4754 | G23: =-G18*Inputs!G65 -> -4690.8883 | H23: =-H18*Inputs!H65 -> -4829.9583 | I23: =-I18*Inputs!I65 -> -4974.1325 | J23: =-J18*Inputs!J65 -> -5125.9303 | K23: =-K18*Inputs!K65 -> -5294.5014
B24: Operating Overhead Expense | D24: -12291 | E24: -11399 | F24: -11360 | G24: =-G18*Inputs!G66 -> -11053.776 | H24: =-H18*Inputs!H66 -> -11142.379 | I24: =-I18*Inputs!I66 -> -11228.735 | J24: =-J18*Inputs!J66 -> -11317.648 | K24: =-K18*Inputs!K66 -> -11427.736
B25: Total SG&A | D25: =SUM(D23:D24) -> -16576 | E25: =SUM(E23:E24) -> -16088 | F25: =SUM(F23:F24) -> -16114 | G25: =SUM(G23:G24) -> -15744.665 | H25: =SUM(H23:H24) -> -15972.337 | I25: =SUM(I23:I24) -> -16202.867 | J25: =SUM(J23:J24) -> -16443.579 | K25: =SUM(K23:K24) -> -16722.237
B27: Operating Income (EBIT) | D27: =D21+D25 -> 6311 | E27: =E21+E25 -> 3702 | F27: =F21+F25 -> 3797 | G27: =G21+G25 -> 4458.6661 | H27: =H21+H25 -> 5069.0652 | I27: =I21+I25 -> 5614.3674 | J27: =J21+J25 -> 6140.9661 | K27: =K21+K25 -> 6709.8631
B29: Interest Income (Expense), net | D29: 161 | E29: 107 | F29: 50 | G29: =G155+G164+G170 -> -110.464 | H29: =H155+H164+H170 -> -74.369196 | I29: =I155+I164+I170 -> -61.197607 | J29: =J155+J164+J170 -> -51.807986 | K29: =K155+K164+K170 -> -39.979468
B30: Other Income (Expense), net | D30: 228 | E30: 76 | F30: 53 | G30: =G18*Inputs!G67 -> 0 | H30: =H18*Inputs!H67 -> 0 | I30: =I18*Inputs!I67 -> 0 | J30: =J18*Inputs!J67 -> 0 | K30: =K18*Inputs!K67 -> 0
B31: Income Before Taxes (EBT) | D31: =D27+D29+D30 -> 6700 | E31: =E27+E29+E30 -> 3885 | F31: =F27+F29+F30 -> 3900 | G31: =G27+G29+G30 -> 4348.2021 | H31: =H27+H29+H30 -> 4994.696 | I31: =I27+I29+I30 -> 5553.1698 | J31: =J27+J29+J30 -> 6089.1581 | K31: =K27+K29+K30 -> 6669.8836
B33: Income Tax Expense | D33: -1000 | E33: -666 | F33: -792 | G33: =-G31*Inputs!G87 -> -956.60447 | H33: =-H31*Inputs!H87 -> -1148.7801 | I33: =-I31*Inputs!I87 -> -1332.7608 | J33: =-J31*Inputs!J87 -> -1461.3979 | K33: =-K31*Inputs!K87 -> -1600.7721
B34: Net Income | D34: =D31+D33 -> 5700 | E34: =E31+E33 -> 3219 | F34: =F31+F33 -> 3108 | G34: =G31+G33 -> 3391.5977 | H34: =H31+H33 -> 3845.9159 | I34: =I31+I33 -> 4220.4091 | J34: =J31+J33 -> 4627.7601 | K34: =K31+K33 -> 5069.1116
B36: Diluted Shares Outstanding | C36: (mm) | D36: =D187 -> 1529.7 | E36: =E187 -> 1487.6 | F36: =F187 -> 1481 | G36: =G187 -> 1458.785 | H36: =H187 -> 1436.9032 | I36: =I187 -> 1415.3497 | J36: =J187 -> 1394.1194 | K36: =K187 -> 1373.2076
B37: Diluted EPS | D37: =D34/D36 -> 3.7262208 | E37: =E34/E36 -> 2.1638881 | F37: =F34/F36 -> 2.098582 | G37: =G34/G36 -> 2.3249469 | H37: =H34/H36 -> 2.6765309 | I37: =I34/I36 -> 2.9818844 | J37: =J34/J36 -> 3.3194861 | K37: =K34/K36 -> 3.6914385
B39: Balance Sheet
B41: All figures in USD millions unless stated | D41: FY2024A | E41: FY2025A | F41: FY2026A | G41: FY2027E | H41: FY2028E | I41: FY2029E | J41: FY2030E | K41: FY2031E
B43: ASSETS
B44: Cash & Cash Equivalents | D44: =D115 -> 9860 | E44: =E115 -> 7464 | F44: =F115 -> 7563 | G44: =G115 -> 5865.3701 | H44: =H115 -> 6194.6598 | I44: =I115 -> 6429.4004 | J44: =J115 -> 6725.1133 | K44: =K115 -> 7199.5752
B45: Short-Term Investments | D45: 1722 | E45: 1687 | F45: 1464 | G45: =F45 -> 1464 | H45: =G45 -> 1464 | I45: =H45 -> 1464 | J45: =I45 -> 1464 | K45: =J45 -> 1464
B46: Accounts Receivable, net | D46: =D125 -> 4427 | E46: =E125 -> 4717 | F46: =F125 -> 5931 | G46: =G125 -> 5942.3433 | H46: =H125 -> 5895.7853 | I46: =I125 -> 6071.7744 | J46: =J125 -> 6257.0695 | K46: =K125 -> 6462.839
B47: Inventories | D47: =D128 -> 7519 | E47: =E128 -> 7489 | F47: =F128 -> 7501 | G47: =G128 -> 6973.6643 | H47: =H128 -> 7043.4981 | I47: =I128 -> 7139.7321 | J47: =J128 -> 7331.1997 | K47: =K128 -> 7545.0055
B48: Prepaid Expenses & Other Current Assets | D48: 1854 | E48: 2005 | F48: 2144 | G48: =F48 -> 2144 | H48: =G48 -> 2144 | I48: =H48 -> 2144 | J48: =I48 -> 2144 | K48: =J48 -> 2144
B49: Total Current Assets | D49: =SUM(D44:D48) -> 25382 | E49: =SUM(E44:E48) -> 23362 | F49: =SUM(F44:F48) -> 24603 | G49: =SUM(G44:G48) -> 22389.378 | H49: =SUM(H44:H48) -> 22741.943 | I49: =SUM(I44:I48) -> 23248.907 | J49: =SUM(J44:J48) -> 23921.382 | K49: =SUM(K44:K48) -> 24815.42
B51: Property, Plant & Equipment, net | D51: =D143 -> 5000 | E51: =E143 -> 4828 | F51: =F143 -> 4796 | G51: =G143 -> 4749.5556 | H51: =H143 -> 4749.5556 | I51: =I143 -> 4749.5556 | J51: =J143 -> 4749.5556 | K51: =K143 -> 4749.5556
B52: Operating Lease Right-of-Use Assets, net | D52: 2718 | E52: 2712 | F52: 2838 | G52: =F52 -> 2838 | H52: =G52 -> 2838 | I52: =H52 -> 2838 | J52: =I52 -> 2838 | K52: =J52 -> 2838
B53: Goodwill & Intangible Assets | D53: 499 | E53: 499 | F53: 499 | G53: =F53 -> 499 | H53: =G53 -> 499 | I53: =H53 -> 499 | J53: =I53 -> 499 | K53: =J53 -> 499
B54: Deferred Tax & Other Non-Current Assets | D54: 4511 | E54: 5178 | F54: 5674 | G54: =F54 -> 5674 | H54: =G54 -> 5674 | I54: =H54 -> 5674 | J54: =I54 -> 5674 | K54: =J54 -> 5674
B55: TOTAL ASSETS | D55: =D49+SUM(D51:D54) -> 38110 | E55: =E49+SUM(E51:E54) -> 36579 | F55: =F49+SUM(F51:F54) -> 38410 | G55: =G49+SUM(G51:G54) -> 36149.933 | H55: =H49+SUM(H51:H54) -> 36502.499 | I55: =I49+SUM(I51:I54) -> 37009.462 | J55: =J49+SUM(J51:J54) -> 37681.938 | K55: =K49+SUM(K51:K54) -> 38575.975
B57: LIABILITIES
...

Sheet DCF
B3: Discounted Cash Flow Valuation
B5: All figures in USD millions unless stated | D5: FY2024A | E5: FY2025A | F5: FY2026A | G5: FY2027E | H5: FY2028E | I5: FY2029E | J5: FY2030E | K5: FY2031E
B7: EBIT | G7: =Model!G27 -> 4458.6661 | H7: =Model!H27 -> 5069.0652 | I7: =Model!I27 -> 5614.3674 | J7: =Model!J27 -> 6140.9661 | K7: =Model!K27 -> 6709.8631
B8: Effective Tax Rate | G8: =Inputs!G87 -> 0.22 | H8: =Inputs!H87 -> 0.23 | I8: =Inputs!I87 -> 0.24 | J8: =Inputs!J87 -> 0.24 | K8: =Inputs!K87 -> 0.24
B9: NOPAT (EBIT, After-Tax) | G9: =G7*(1-G8) -> 3477.7596 | H9: =H7*(1-H8) -> 3903.1802 | I9: =I7*(1-I8) -> 4266.9192 | J9: =J7*(1-J8) -> 4667.1342 | K9: =K7*(1-K8) -> 5099.496
B10: Add: Depreciation & Amortization | G10: =-Model!G142 -> 789.55546 | H10: =-Model!H142 -> 812.96328 | I10: =-Model!I142 -> 837.23023 | J10: =-Model!J142 -> 862.78035 | K10: =-Model!K142 -> 891.15369
B11: Less: Capital Expenditures | G11: =Model!G141 -> -743.11102 | H11: =Model!H141 -> -812.96328 | I11: =Model!I141 -> -837.23023 | J11: =Model!J141 -> -862.78035 | K11: =Model!K141 -> -891.15369
B12: Add (Less): Net Change in Working Capital | G12: =Model!G137 -> 259.03765 | H12: =Model!H137 -> 118.74313 | I12: =Model!I137 -> -149.84371 | J12: =Model!J137 -> -280.02112 | K12: =Model!K137 -> -311.54721
B13: Unlevered Free Cash Flow | G13: =SUM(G9:G12) -> 3783.2417 | H13: =SUM(H9:H12) -> 4021.9233 | I13: =SUM(I9:I12) -> 4117.0755 | J13: =SUM(J9:J12) -> 4387.1131 | K13: =SUM(K9:K12) -> 4787.9488
B15: Discount Period (Mid-Year Convention) | G15: 0.5 | H15: 1.5 | I15: 2.5 | J15: 3.5 | K15: 4.5
B16: Discount Factor | G16: =1/(1+Inputs!F116)^G15 -> 0.95862328 | H16: =1/(1+Inputs!F116)^H15 -> 0.88093511 | I16: =1/(1+Inputs!F116)^I15 -> 0.80954289 | J16: =1/(1+Inputs!F116)^J15 -> 0.7439364 | K16: =1/(1+Inputs!F116)^K15 -> 0.68364676
B17: PV of Unlevered Free Cash Flow | G17: =G13*G16 -> 3626.7036 | H17: =H13*H16 -> 3543.0534 | I17: =I13*I16 -> 3332.9492 | J17: =J13*J16 -> 3263.7331 | K17: =K13*K16 -> 3273.2656
B19: TERMINAL VALUE
B21: Terminal Year Unlevered FCF (FY31E) | F21: =K13 -> 4787.9488
B22: Terminal Value -- Perpetuity Growth Method | F22: =F21*(1+Inputs!F117)/(Inputs!F116-Inputs!F117) -> 71620.9
B23: PV of Terminal Value (Perpetuity Growth) | F23: =F22*K16 -> 48963.396
B24: Terminal Year EBITDA (FY31E) | F24: =K7-Model!K142 -> 7601.0168
B25: Terminal Value -- Exit Multiple Cross-Check | F25: =F24*Inputs!F118 -> 79853.823
B26: PV of Terminal Value (Exit Multiple) | F26: =F25*K16 -> 54591.807
B28: ENTERPRISE & EQUITY VALUE
B30: Enterprise Value -- Perpetuity Growth Method | F30: =SUM(G17:K17)+F23 -> 66003.101
B31: Enterprise Value -- Exit Multiple Method | F31: =SUM(G17:K17)+F26 -> 71631.512
B32: Net Debt / (Net Cash) | F32: =Model!F64+Model!F65-Model!F44-Model!F45 -> -1085
B33: Equity Value -- Perpetuity Growth Method | F33: =F30-F32 -> 67088.101
B34: Equity Value -- Exit Multiple Method | F34: =F31-F32 -> 72716.512
B35: Implied Share Price -- Perpetuity Growth Method | F35: =F33/Inputs!F120 -> 45.29919
B36: Implied Share Price -- Exit Multiple Method | F36: =F34/Inputs!F120 -> 49.099603
B37: Implied Upside / (Downside) -- Perpetuity Growth | F37: =F35/Inputs!F119-1 -> 0.14391894
B38: Implied Upside / (Downside) -- Exit Multiple | F38: =F36/Inputs!F119-1 -> 0.23988896
B41: SENSITIVITY -- IMPLIED SHARE PRICE (PERPETUITY GROWTH METHOD)
B43: WACC (rows) vs. Terminal Growth Rate (columns)
B45: WACC (down) | C45: Terminal Growth Rate -> | D45: =Inputs!F117+(-0.01) -> 0.01 | E45: =Inputs!F117+(-0.005) -> 0.015 | F45: =Inputs!F117+(0) -> 0.02 | G45: =Inputs!F117+(0.005) -> 0.025 | H45: =Inputs!F117+(0.01) -> 0.03
C46: =Inputs!F116+(-0.01) -> 0.078188305 | D46: =($G$13/(1+$C46)^$G$15+$H$13/(1+$C46)^$H$15+$I$13/(1+$C46)^$I$15+$J$13/(1+$C46)^$J$15+$K$13/(1+$C46)^$K$15+($K$13*(1+D$45)/($C46-D$45))/(1+$C46)^$K$15-$F$32)/Inputs!$F$120 -> 46.627101 | E46: =($G$13/(1+$C46)^$G$15+$H$13/(1+$C46)^$H$15+$I$13/(1+$C46)^$I$15+$J$13/(1+$C46)^$J$15+$K$13/(1+$C46)^$K$15+($K$13*(1+E$45)/($C46-E$45))/(1+$C46)^$K$15-$F$32)/Inputs!$F$120 -> 49.509716 | F46: =($G$13/(1+$C46)^$G$15+$H$13/(1+$C46)^$H$15+$I$13/(1+$C46)^$I$15+$J$13/(1+$C46)^$J$15+$K$13/(1+$C46)^$K$15+($K$13*(1+F$45)/($C46-F$45))/(1+$C46)^$K$15-$F$32)/Inputs!$F$120 -> 52.887726 | G46: =($G$13/(1+$C46)^$G$15+$H$13/(1+$C46)^$H$15+$I$13/(1+$C46)^$I$15+$J$13/(1+$C46)^$J$15+$K$13/(1+$C46)^$K$15+($K$13*(1+G$45)/($C46-G$45))/(1+$C46)^$K$15-$F$32)/Inputs!$F$120 -> 56.900839 | H46: =($G$13/(1+$C46)^$G$15+$H$13/(1+$C46)^$H$15+$I$13/(1+$C46)^$I$15+$J$13/(1+$C46)^$J$15+$K$13/(1+$C46)^$K$15+($K$13*(1+H$45)/($C46-H$45))/(1+$C46)^$K$15-$F$32)/Inputs!$F$120 -> 61.746751
C47: =Inputs!F116+(-0.005) -> 0.083188305 | D47: =($G$13/(1+$C47)^$G$15+$H$13/(1+$C47)^$H$15+$I$13/(1+$C47)^$I$15+$J$13/(1+$C47)^$J$15+$K$13/(1+$C47)^$K$15+($K$13*(1+D$45)/($C47-D$45))/(1+$C47)^$K$15-$F$32)/Inputs!$F$120 -> 43.507651 | E47: =($G$13/(1+$C47)^$G$15+$H$13/(1+$C47)^$H$15+$I$13/(1+$C47)^$I$15+$J$13/(1+$C47)^$J$15+$K$13/(1+$C47)^$K$15+($K$13*(1+E$45)/($C47-E$45))/(1+$C47)^$K$15-$F$32)/Inputs!$F$120 -> 45.956427 | F47: =($G$13/(1+$C47)^$G$15+$H$13/(1+$C47)^$H$15+$I$13/(1+$C47)^$I$15+$J$13/(1+$C47)^$J$15+$K$13/(1+$C47)^$K$15+($K$13*(1+F$45)/($C47-F$45))/(1+$C47)^$K$15-$F$32)/Inputs!$F$120 -> 48.792738 | G47: =($G$13/(1+$C47)^$G$15+$H$13/(1+$C47)^$H$15+$I$13/(1+$C47)^$I$15+$J$13/(1+$C47)^$J$15+$K$13/(1+$C47)^$K$15+($K$13*(1+G$45)/($C47-G$45))/(1+$C47)^$K$15-$F$32)/Inputs!$F$120 -> 52.116487 | H47: =($G$13/(1+$C47)^$G$15+$H$13/(1+$C47)^$H$15+$I$13/(1+$C47)^$I$15+$J$13/(1+$C47)^$J$15+$K$13/(1+$C47)^$K$15+($K$13*(1+H$45)/($C47-H$45))/(1+$C47)^$K$15-$F$32)/Inputs!$F$120 -> 56.065138
C48: =Inputs!F116+(0) -> 0.088188305 | D48: =($G$13/(1+$C48)^$G$15+$H$13/(1+$C48)^$H$15+$I$13/(1+$C48)^$I$15+$J$13/(1+$C48)^$J$15+$K$13/(1+$C48)^$K$15+($K$13*(1+D$45)/($C48-D$45))/(1+$C48)^$K$15-$F$32)/Inputs!$F$120 -> 40.788131 | E48: =($G$13/(1+$C48)^$G$15+$H$13/(1+$C48)^$H$15+$I$13/(1+$C48)^$I$15+$J$13/(1+$C48)^$J$15+$K$13/(1+$C48)^$K$15+($K$13*(1+E$45)/($C48-E$45))/(1+$C48)^$K$15-$F$32)/Inputs!$F$120 -> 42.88957 | F48: =($G$13/(1+$C48)^$G$15+$H$13/(1+$C48)^$H$15+$I$13/(1+$C48)^$I$15+$J$13/(1+$C48)^$J$15+$K$13/(1+$C48)^$K$15+($K$13*(1+F$45)/($C48-F$45))/(1+$C48)^$K$15-$F$32)/Inputs!$F$120 -> 45.29919 | G48: =($G$13/(1+$C48)^$G$15+$H$13/(1+$C48)^$H$15+$I$13/(1+$C48)^$I$15+$J$13/(1+$C48)^$J$15+$K$13/(1+$C48)^$K$15+($K$13*(1+G$45)/($C48-G$45))/(1+$C48)^$K$15-$F$32)/Inputs!$F$120 -> 48.09015 | H48: =($G$13/(1+$C48)^$G$15+$H$13/(1+$C48)^$H$15+$I$13/(1+$C48)^$I$15+$J$13/(1+$C48)^$J$15+$K$13/(1+$C48)^$K$15+($K$13*(1+H$45)/($C48-H$45))/(1+$C48)^$K$15-$F$32)/Inputs!$F$120 -> 51.360753
C49: =Inputs!F116+(0.005) -> 0.093188305 | D49: =($G$13/(1+$C49)^$G$15+$H$13/(1+$C49)^$H$15+$I$13/(1+$C49)^$I$15+$J$13/(1+$C49)^$J$15+$K$13/(1+$C49)^$K$15+($K$13*(1+D$45)/($C49-D$45))/(1+$C49)^$K$15-$F$32)/Inputs!$F$120 -> 38.396403 | E49: =($G$13/(1+$C49)^$G$15+$H$13/(1+$C49)^$H$15+$I$13/(1+$C49)^$I$15+$J$13/(1+$C49)^$J$15+$K$13/(1+$C49)^$K$15+($K$13*(1+E$45)/($C49-E$45))/(1+$C49)^$K$15-$F$32)/Inputs!$F$120 -> 40.215802 | F49: =($G$13/(1+$C49)^$G$15+$H$13/(1+$C49)^$H$15+$I$13/(1+$C49)^$I$15+$J$13/(1+$C49)^$J$15+$K$13/(1+$C49)^$K$15+($K$13*(1+F$45)/($C49-F$45))/(1+$C49)^$K$15-$F$32)/Inputs!$F$120 -> 42.283792 | G49: =($G$13/(1+$C49)^$G$15+$H$13/(1+$C49)^$H$15+$I$13/(1+$C49)^$I$15+$J$13/(1+$C49)^$J$15+$K$13/(1+$C49)^$K$15+($K$13*(1+G$45)/($C49-G$45))/(1+$C49)^$K$15-$F$32)/Inputs!$F$120 -> 44.655059 | H49: =($G$13/(1+$C49)^$G$15+$H$13/(1+$C49)^$H$15+$I$13/(1+$C49)^$I$15+$J$13/(1+$C49)^$J$15+$K$13/(1+$C49)^$K$15+($K$13*(1+H$45)/($C49-H$45))/(1+$C49)^$K$15-$F$32)/Inputs!$F$120 -> 47.401596
C50: =Inputs!F116+(0.01) -> 0.098188305 | D50: =($G$13/(1+$C50)^$G$15+$H$13/(1+$C50)^$H$15+$I$13/(1+$C50)^$I$15+$J$13/(1+$C50)^$J$15+$K$13/(1+$C50)^$K$15+($K$13*(1+D$45)/($C50-D$45))/(1+$C50)^$K$15-$F$32)/Inputs!$F$120 -> 36.276692 | E50: =($G$13/(1+$C50)^$G$15+$H$13/(1+$C50)^$H$15+$I$13/(1+$C50)^$I$15+$J$13/(1+$C50)^$J$15+$K$13/(1+$C50)^$K$15+($K$13*(1+E$45)/($C50-E$45))/(1+$C50)^$K$15-$F$32)/Inputs!$F$120 -> 37.864223 | F50: =($G$13/(1+$C50)^$G$15+$H$13/(1+$C50)^$H$15+$I$13/(1+$C50)^$I$15+$J$13/(1+$C50)^$J$15+$K$13/(1+$C50)^$K$15+($K$13*(1+F$45)/($C50-F$45))/(1+$C50)^$K$15-$F$32)/Inputs!$F$120 -> 39.654794 | G50: =($G$13/(1+$C50)^$G$15+$H$13/(1+$C50)^$H$15+$I$13/(1+$C50)^$I$15+$J$13/(1+$C50)^$J$15+$K$13/(1+$C50)^$K$15+($K$13*(1+G$45)/($C50-G$45))/(1+$C50)^$K$15-$F$32)/Inputs!$F$120 -> 41.690018 | H50: =($G$13/(1+$C50)^$G$15+$H$13/(1+$C50)^$H$15+$I$13/(1+$C50)^$I$15+$J$13/(1+$C50)^$J$15+$K$13/(1+$C50)^$K$15+($K$13*(1+H$45)/($C50-H$45))/(1+$C50)^$K$15-$F$32)/Inputs!$F$120 -> 44.023712
B52: All figures in USD millions except per-share data. Explicit forecast period = FY2027E-FY2031E (5 years); mid-year discounting convention.

Sheet Comps
B3: Comparable Company Analysis
B5: Peer Company | C5: Ticker | D5: Price | E5: Dil. Shares | F5: Mkt Cap | G5: Total Debt | H5: Cash & Equiv. | I5: Net Debt | J5: Enterprise Value | K5: LTM Revenue | L5: LTM EBITDA | M5: LTM EPS | N5: EV / Rev | O5: EV / EBITDA | P5: P / E
B7: Adidas AG | C7: ADS.DE | D7: 179.16 | E7: 174 | F7: =D7*E7 -> 31173.84 | G7: 6940 | H7: 1810 | I7: =G7-H7 -> 5130 | J7: =F7+I7 -> 36303.84 | K7: 30210 | L7: 3860 | M7: 9.01 | N7: =J7/K7 -> 1.201716 | O7: =IFERROR(J7/L7,"n.m.") -> 9.4051399 | P7: =IF(M7<0,"n.m.",D7/M7) -> 19.884573
B8: Lululemon Athletica | C8: LULU | D8: 120.81 | E8: 113.6 | F8: =D8*E8 -> 13724.016 | G8: 2140 | H8: 1510 | I8: =G8-H8 -> 630 | J8: =F8+I8 -> 14354.016 | K8: 10180 | L8: 2570 | M8: 12.35 | N8: =J8/K8 -> 1.4100212 | O8: =IFERROR(J8/L8,"n.m.") -> 5.5852202 | P8: =IF(M8<0,"n.m.",D8/M8) -> 9.7821862
B9: Under Armour | C9: UAA | D9: 5.2 | E9: 429.6 | F9: =D9*E9 -> 2233.92 | G9: 1380 | H9: 396 | I9: =G9-H9 -> 984 | J9: =F9+I9 -> 3217.92 | K9: 4930 | L9: 173 | M9: -1.15 | N9: =J9/K9 -> 0.65272211 | O9: =IFERROR(J9/L9,"n.m.") -> 18.600694 | P9: =IF(M9<0,"n.m.",D9/M9) -> n.m.
B10: Deckers Brands | C10: DECK | D10: 87.76 | E10: 136.2 | F10: =D10*E10 -> 11952.912 | G10: 472 | H10: 1600 | I10: =G10-H10 -> -1128 | J10: =F10+I10 -> 10824.912 | K10: 5530 | L10: 1330 | M10: 7.05 | N10: =J10/K10 -> 1.9574886 | O10: =IFERROR(J10/L10,"n.m.") -> 8.1390316 | P10: =IF(M10<0,"n.m.",D10/M10) -> 12.448227
B11: VF Corporation | C11: VFC | D11: 13.67 | E11: 393.1 | F11: =D11*E11 -> 5373.677 | G11: 4950 | H11: 670 | I11: =G11-H11 -> 4280 | J11: =F11+I11 -> 9653.677 | K11: 9510 | L11: 894 | M11: 0.69 | N11: =J11/K11 -> 1.015108 | O11: =IFERROR(J11/L11,"n.m.") -> 10.798296 | P11: =IF(M11<0,"n.m.",D11/M11) -> 19.811594
B12: Puma SE | C12: PUM.DE | D12: 29.73 | E12: 147.2 | F12: =D12*E12 -> 4376.256 | G12: 3090 | H12: 432 | I12: =G12-H12 -> 2658 | J12: =F12+I12 -> 7034.256 | K12: 8320 | L12: 180 | M12: -4.88 | N12: =J12/K12 -> 0.84546346 | O12: =IFERROR(J12/L12,"n.m.") -> 39.0792 | P12: =IF(M12<0,"n.m.",D12/M12) -> n.m.
B13: Average | N13: =AVERAGE(N7:N12) -> 1.1804199 | O13: =AVERAGE(O7:O11) -> 10.505676 | P13: =AVERAGE(P7,P8,P10,P11) -> 15.481645
B14: Median | N14: =MEDIAN(N7:N12) -> 1.108412 | O14: =MEDIAN(O7:O11) -> 9.4051399 | P14: =MEDIAN(P7,P8,P10,P11) -> 16.129911
B16: Skechers (SKX) excluded -- taken private by 3G Capital, deal closed Sept-2025. Puma excluded from EV/EBITDA avg/median (transition-year margins). Under Armour and Puma excluded from P/E avg/median (loss-making, n.m.).
B18: NIKE IMPLIED VALUATION -- TRADING COMPS
B20: NIKE LTM Revenue | F20: =Model!F18 -> 46398
B21: NIKE LTM EBITDA | F21: =Model!F27-Model!F142 -> 4544
B22: NIKE LTM EPS (Diluted) | F22: =Model!F37 -> 2.098582
B23: Implied Enterprise Value -- EV/Revenue Method | F23: =F20*N13 -> 54769.122
B24: Implied Enterprise Value -- EV/EBITDA Method | F24: =F21*O13 -> 47737.793
B25: Less: Net Debt (FY26A) | F25: =Model!F64+Model!F65-Model!F44-Model!F45 -> -1085
B26: Implied Equity Value -- EV/Revenue Method | F26: =F23-F25 -> 55854.122
B27: Implied Equity Value -- EV/EBITDA Method | F27: =F24-F25 -> 48822.793
B28: Implied Equity Value -- P/E Method | F28: =F22*P13*F29 -> 48116.953
B29: Diluted Shares Outstanding (FY26A) | F29: =Model!F36 -> 1481
B30: Implied Share Price -- EV/Revenue Method | F30: =F26/F29 -> 37.71379
B31: Implied Share Price -- EV/EBITDA Method | F31: =F27/F29 -> 32.966099
B32: Implied Share Price -- P/E Method | F32: =F28/F29 -> 32.489502
B34: All figures in USD millions except per-share data. Market data as of late August 2026.
